<?xml version="1.0"?>
<robot name="six_wheel_rover">

  <material name="blue"><color rgba="0 0 0.8 1"/></material>
  <material name="grey"><color rgba="0.5 0.5 0.5 1"/></material>

  <link name="base_link">
    <visual>
      <geometry><box size="0.5 0.3 0.1"/></geometry> <material name="blue"/>
    </visual>
  </link>

  <link name="front_left_wheel">
    <visual>
      <geometry><cylinder length="0.05" radius="0.06"/></geometry>
      <material name="grey"/>
    </visual>
  </link>
  <joint name="base_to_fl_wheel" type="continuous">
    <parent link="base_link"/>
    <child link="front_left_wheel"/>
    <origin xyz="0.2 0.2 -0.05" rpy="1.57 0 0"/> </joint>

  <link name="camera_link">
    <visual><geometry><box size="0.05 0.15 0.05"/></geometry></visual>
  </link>
  <joint name="base_to_camera" type="fixed">
    <parent link="base_link"/>
    <child link="camera_link"/>
    <origin xyz="0.25 0 0.2" rpy="0 0 0"/> </joint>

  <link name="arm_base_link">
    <visual><geometry><cylinder length="0.05" radius="0.05"/></geometry></visual>
  </link>
  <joint name="chassis_to_arm" type="fixed">
    <parent link="base_link"/>
    <child link="arm_base_link"/>
    <origin xyz="0.2 0 0.1" rpy="0 0 0"/> </joint>

  <link name="link_1">
    <visual><geometry><box size="0.05 0.05 0.1"/></geometry></visual>
  </link>
  <joint name="joint_1" type="revolute">
    <parent link="arm_base_link"/>
    <child link="link_1"/>
    <origin xyz="0 0 0.05" rpy="0 0 0"/>
    <axis xyz="0 0 1"/> <limit lower="-3.14" upper="3.14" effort="10" velocity="1"/>
  </joint>

  <link name="link_2">
    <visual><geometry><box size="0.05 0.05 0.2"/></geometry></visual>
  </link>
  <joint name="joint_2" type="revolute">
    <parent link="link_1"/>
    <child link="link_2"/>
    <origin xyz="0 0 0.05" rpy="0 0 0"/>
    <axis xyz="0 1 0"/> <limit lower="-1.57" upper="1.57" effort="20" velocity="1"/>
  </joint>

  </robot>
